  0%|                                                                                                                                                                            | 0/10000000 [00:00<?, ?it/s]
Traceback (most recent call last):
  File "C:\Users\kms\Capstone_Design_Closet\project\lib\site-packages\pandas\core\indexes\base.py", line 3805, in get_loc
    return self._engine.get_loc(casted_key)
  File "index.pyx", line 167, in pandas._libs.index.IndexEngine.get_loc
  File "index.pyx", line 196, in pandas._libs.index.IndexEngine.get_loc
  File "pandas\\_libs\\hashtable_class_helper.pxi", line 7081, in pandas._libs.hashtable.PyObjectHashTable.get_item
  File "pandas\\_libs\\hashtable_class_helper.pxi", line 7089, in pandas._libs.hashtable.PyObjectHashTable.get_item
KeyError: 'img_name'

The above exception was the direct cause of the following exception:

Traceback (most recent call last):
  File "C:\Users\kms\Capstone_Design_Closet\ai\train.py", line 130, in <module>
    train(args)
  File "C:\Users\kms\Capstone_Design_Closet\ai\train.py", line 75, in train
    for idx, (batch_images, num_crops) in enumerate(dataloader):
  File "C:\Users\kms\Capstone_Design_Closet\project\lib\site-packages\torch\utils\data\dataloader.py", line 630, in __next__
    data = self._next_data()
  File "C:\Users\kms\Capstone_Design_Closet\project\lib\site-packages\torch\utils\data\dataloader.py", line 673, in _next_data
    data = self._dataset_fetcher.fetch(index)  # may raise StopIteration
  File "C:\Users\kms\Capstone_Design_Closet\project\lib\site-packages\torch\utils\data\_utils\fetch.py", line 52, in fetch
    data = [self.dataset[idx] for idx in possibly_batched_index]
  File "C:\Users\kms\Capstone_Design_Closet\project\lib\site-packages\torch\utils\data\_utils\fetch.py", line 52, in <listcomp>
    data = [self.dataset[idx] for idx in possibly_batched_index]
  File "C:\Users\kms\Capstone_Design_Closet\ai\model\dataset.py", line 27, in __getitem__
    x = meta.loc[meta["img_name"] == self.image_filenames[idx], "x"].values[0]
  File "C:\Users\kms\Capstone_Design_Closet\project\lib\site-packages\pandas\core\frame.py", line 4102, in __getitem__
    indexer = self.columns.get_loc(key)
  File "C:\Users\kms\Capstone_Design_Closet\project\lib\site-packages\pandas\core\indexes\base.py", line 3812, in get_loc
    raise KeyError(key) from err
KeyError: 'img_name'
